Workbook

Sheet Assumptions & Summary
B2: RETIREMENT PLAN — SCENARIO 5: DELAYED RETIREMENT + GROWTH REINVEST (4% GROWTH)
B3: Retire at 57 | Cap Income at $300K | Reinvest ALL Surplus in Growth | Your SS Only at 67
B5: PERSONAL DETAILS
B6: Current Age | C6: 51
B7: Retirement Age | C7: 57
B8: Plan End Age | C8: 90
B9: Years Until Retirement | C9: =C7-C6 -> 6
B10: Years in Retirement | C10: =C8-C7 -> 33
B11: SS Start Age (You Only) | C11: 67
B12: SS Benefit (Annual, today $) | C12: 36000
B13: Medicare Eligibility Age | C13: 65
B15: ACCUMULATION PHASE (Ages 51-57) | E15: EXPENSE ASSUMPTIONS
B16: Current Savings | C16: 8600000 | E16: Total Annual Expenses (Today $, incl. mortgage & medical) | F16: 225000
B17: Annual Savings While Working | C17: 150000 | E17: Monthly Mortgage Payment | F17: 2500
B18: Pre-Retirement Growth Rate (Growth Portfolio) | C18: 0.04 | E18: Annual Mortgage Cost | F18: =F17*12 -> 30000
B19: Portfolio at Retirement (Age 57) | C19: =C16*(1+C18)^C9 + C17*((1+C18)^C9-1)/C18 -> 11876690 | E19: Mortgage Remaining Years from Now | F19: 15
E20: Pre-Medicare Annual Medical (Out of Pocket) | F20: 25000
B21: DISTRIBUTION PHASE (Ages 57-90) | E21: Post-Medicare Annual Medical (Est.) | F21: 8000
B22: Post-Retirement Total Return | C22: 0.04
B23: Income Portion (Yield on Income Sleeve) | C23: 0.04 | E23: INCOME-CAPPING STRATEGY
B24: Growth Sleeve Return | C24: 0.04 | E24: 1. Portfolio split: Income Sleeve + Growth Sleeve
B25: Effective Tax Rate on Income | C25: 0.2 | E25: 2. Income Sleeve sized to generate ~$300K/yr at 4% yield
B26: Inflation Rate (Annual) | C26: 0.03 | E26: 3. ALL surplus above expenses reinvested into Growth Sleeve
B27: Target Annual Income (Today $) | C27: 300000 | E27: 4. Growth Sleeve compounds at 8% (equities, no withdrawals)
B28: Target Nest Egg at Age 90 (Real $, Today) | C28: 4250000 | E28: 5. As expenses inflate, rebalance from Growth → Income
B29: Target Nest Egg at Age 90 (Nominal $) | C29: =C28*(1+C26)^(C8-C6) -> 13459865 | E29: 6. Result: maximum long-term wealth accumulation
B32: KEY METRICS SUMMARY
B33: Portfolio at Retirement (Age 57) | C33: =C19 -> 11876690
B34: Initial Income Sleeve (generates ~$300K) | C34: =C27/C23 -> 7500000
B35: Initial Growth Sleeve (remainder) | C35: =C19-C34 -> 4376689.9
B36: Ending Total Portfolio at Age 90 | C36: ='Year-by-Year'!H37 -> 39602033
B37: — Income Sleeve at 90 | C37: ='Year-by-Year'!E37 -> 19892514
B38: — Growth Sleeve at 90 | C38: ='Year-by-Year'!I37 -> 19709519
B39: Preservation Target ($4.25M Real, Nominal) | C39: =C29 -> 13459865
B40: Surplus / (Shortfall) at 90 | C40: =C36-C39 -> 26142168
B41: Ending Portfolio in Real Dollars | C41: =C36/(1+C26)^(C8-C6) -> 12504482
B43: CURRENT ACCOUNTS
B44: Account | C44: Balance ($)
B45: Fidelity – Saurabh | C45: 1800000
B46: Fidelity – Kangan | C46: 2450000
...

Sheet Year-by-Year
A1: YEAR-BY-YEAR — SCENARIO 5: DELAYED RETIREMENT + GROWTH REINVEST (4% GROWTH)
A2: Income capped at ~$300K (inflating) | Surplus reinvested in Growth Sleeve at 4% | Income Sleeve yields 4%
A3: Age | B3: Year | C3: Income from Income Sleeve | D3: Social Security | E3: Income Sleeve Balance (BOY) | F3: Total Expenses | G3: Net Cash Flow (After Tax) | H3: Total Portfolio (BOY) | I3: Growth Sleeve Balance (BOY) | J3: Surplus Reinvested | K3: Notes
A4: 57 | B4: 2032 | C4: =E4*'Assumptions & Summary'!$C$23 -> 300000 | D4: 0 | E4: ='Assumptions & Summary'!C27/'Assumptions & Summary'!C23 -> 7500000 | F4: =(('Assumptions & Summary'!$F$16-'Assumptions & Summary'!$F$18-'Assumptions & Summary'!$F$20)*(1+'Assumptions & Summary'!$C$26)^6+'Assumptions & Summary'!$F$18*(1+'Assumptions & Summary'!$C$26)^6+'Assumptions & Summary'!$F$20*(1+'Assumptions & Summary'!$C$26)^6) -> 268661.77 | G4: =(C4*(1-'Assumptions & Summary'!$C$25)+D4*0.85*(1-'Assumptions & Summary'!$C$25))-F4 -> -28661.767 | H4: =E4+I4 -> 11876690 | I4: ='Assumptions & Summary'!C19-E4 -> 4376689.9 | J4: =MAX(0,G4) -> 0 | K4: Retirement begins
A5: 58 | B5: 2033 | C5: =E5*'Assumptions & Summary'!$C$23 -> 309000 | D5: 0 | E5: =E4*(1+'Assumptions & Summary'!$C$26) -> 7725000 | F5: =(('Assumptions & Summary'!$F$16-'Assumptions & Summary'!$F$18-'Assumptions & Summary'!$F$20)*(1+'Assumptions & Summary'!$C$26)^7+'Assumptions & Summary'!$F$18*(1+'Assumptions & Summary'!$C$26)^7+'Assumptions & Summary'!$F$20*(1+'Assumptions & Summary'!$C$26)^7) -> 276721.62 | G5: =(C5*(1-'Assumptions & Summary'!$C$25)+D5*0.85*(1-'Assumptions & Summary'!$C$25))-F5 -> -29521.62 | H5: =E5+I5 -> 12276757 | I5: =I4*(1+'Assumptions & Summary'!$C$24)+J4 -> 4551757.5 | J5: =MAX(0,G5) -> 0
A6: 59 | B6: 2034 | C6: =E6*'Assumptions & Summary'!$C$23 -> 318270 | D6: 0 | E6: =E5*(1+'Assumptions & Summary'!$C$26) -> 7956750 | F6: =(('Assumptions & Summary'!$F$16-'Assumptions & Summary'!$F$18-'Assumptions & Summary'!$F$20)*(1+'Assumptions & Summary'!$C$26)^8+'Assumptions & Summary'!$F$18*(1+'Assumptions & Summary'!$C$26)^8+'Assumptions & Summary'!$F$20*(1+'Assumptions & Summary'!$C$26)^8) -> 285023.27 | G6: =(C6*(1-'Assumptions & Summary'!$C$25)+D6*0.85*(1-'Assumptions & Summary'!$C$25))-F6 -> -30407.268 | H6: =E6+I6 -> 12690578 | I6: =I5*(1+'Assumptions & Summary'!$C$24)+J5 -> 4733827.8 | J6: =MAX(0,G6) -> 0
A7: 60 | B7: 2035 | C7: =E7*'Assumptions & Summary'!$C$23 -> 327818.1 | D7: 0 | E7: =E6*(1+'Assumptions & Summary'!$C$26) -> 8195452.5 | F7: =(('Assumptions & Summary'!$F$16-'Assumptions & Summary'!$F$18-'Assumptions & Summary'!$F$20)*(1+'Assumptions & Summary'!$C$26)^9+'Assumptions & Summary'!$F$18*(1+'Assumptions & Summary'!$C$26)^9+'Assumptions & Summary'!$F$20*(1+'Assumptions & Summary'!$C$26)^9) -> 293573.97 | G7: =(C7*(1-'Assumptions & Summary'!$C$25)+D7*0.85*(1-'Assumptions & Summary'!$C$25))-F7 -> -31319.486 | H7: =E7+I7 -> 13118633 | I7: =I6*(1+'Assumptions & Summary'!$C$24)+J6 -> 4923180.9 | J7: =MAX(0,G7) -> 0
A8: 61 | B8: 2036 | C8: =E8*'Assumptions & Summary'!$C$23 -> 337652.64 | D8: 0 | E8: =E7*(1+'Assumptions & Summary'!$C$26) -> 8441316.1 | F8: =(('Assumptions & Summary'!$F$16-'Assumptions & Summary'!$F$18-'Assumptions & Summary'!$F$20)*(1+'Assumptions & Summary'!$C$26)^10+'Assumptions & Summary'!$F$18*(1+'Assumptions & Summary'!$C$26)^10+'Assumptions & Summary'!$F$20*(1+'Assumptions & Summary'!$C$26)^10) -> 302381.19 | G8: =(C8*(1-'Assumptions & Summary'!$C$25)+D8*0.85*(1-'Assumptions & Summary'!$C$25))-F8 -> -32259.071 | H8: =E8+I8 -> 13561424 | I8: =I7*(1+'Assumptions & Summary'!$C$24)+J7 -> 5120108.1 | J8: =MAX(0,G8) -> 0
A9: 62 | B9: 2037 | C9: =E9*'Assumptions & Summary'!$C$23 -> 347782.22 | D9: 0 | E9: =E8*(1+'Assumptions & Summary'!$C$26) -> 8694555.6 | F9: =(('Assumptions & Summary'!$F$16-'Assumptions & Summary'!$F$18-'Assumptions & Summary'!$F$20)*(1+'Assumptions & Summary'!$C$26)^11+'Assumptions & Summary'!$F$18*(1+'Assumptions & Summary'!$C$26)^11+'Assumptions & Summary'!$F$20*(1+'Assumptions & Summary'!$C$26)^11) -> 311452.62 | G9: =(C9*(1-'Assumptions & Summary'!$C$25)+D9*0.85*(1-'Assumptions & Summary'!$C$25))-F9 -> -33226.843 | H9: =E9+I9 -> 14019468 | I9: =I8*(1+'Assumptions & Summary'!$C$24)+J8 -> 5324912.4 | J9: =MAX(0,G9) -> 0
A10: 63 | B10: 2038 | C10: =E10*'Assumptions & Summary'!$C$23 -> 358215.69 | D10: 0 | E10: =E9*(1+'Assumptions & Summary'!$C$26) -> 8955392.2 | F10: =(('Assumptions & Summary'!$F$16-'Assumptions & Summary'!$F$18-'Assumptions & Summary'!$F$20)*(1+'Assumptions & Summary'!$C$26)^12+'Assumptions & Summary'!$F$18*(1+'Assumptions & Summary'!$C$26)^12+'Assumptions & Summary'!$F$20*(1+'Assumptions & Summary'!$C$26)^12) -> 320796.2 | G10: =(C10*(1-'Assumptions & Summary'!$C$25)+D10*0.85*(1-'Assumptions & Summary'!$C$25))-F10 -> -34223.648 | H10: =E10+I10 -> 14493301 | I10: =I9*(1+'Assumptions & Summary'!$C$24)+J9 -> 5537908.9 | J10: =MAX(0,G10) -> 0
A11: 64 | B11: 2039 | C11: =E11*'Assumptions & Summary'!$C$23 -> 368962.16 | D11: 0 | E11: =E10*(1+'Assumptions & Summary'!$C$26) -> 9224054 | F11: =(('Assumptions & Summary'!$F$16-'Assumptions & Summary'!$F$18-'Assumptions & Summary'!$F$20)*(1+'Assumptions & Summary'!$C$26)^13+'Assumptions & Summary'!$F$18*(1+'Assumptions & Summary'!$C$26)^13+'Assumptions & Summary'!$F$20*(1+'Assumptions & Summary'!$C$26)^13) -> 330420.09 | G11: =(C11*(1-'Assumptions & Summary'!$C$25)+D11*0.85*(1-'Assumptions & Summary'!$C$25))-F11 -> -35250.358 | H11: =E11+I11 -> 14983479 | I11: =I10*(1+'Assumptions & Summary'!$C$24)+J10 -> 5759425.3 | J11: =MAX(0,G11) -> 0
A12: 65 | B12: 2040 | C12: =E12*'Assumptions & Summary'!$C$23 -> 380031.02 | D12: 0 | E12: =E11*(1+'Assumptions & Summary'!$C$26) -> 9500775.6 | F12: =(('Assumptions & Summary'!$F$16-'Assumptions & Summary'!$F$18-'Assumptions & Summary'!$F$20)*(1+'Assumptions & Summary'!$C$26)^14+'Assumptions & Summary'!$F$18*(1+'Assumptions & Summary'!$C$26)^14+'Assumptions & Summary'!$F$21*(1+'Assumptions & Summary'!$C$26)^14) -> 314618.66 | G12: =(C12*(1-'Assumptions & Summary'!$C$25)+D12*0.85*(1-'Assumptions & Summary'!$C$25))-F12 -> -10593.843 | H12: =E12+I12 -> 15490578 | I12: =I11*(1+'Assumptions & Summary'!$C$24)+J11 -> 5989802.3 | J12: =MAX(0,G12) -> 0 | K12: Medicare starts
A13: 66 | B13: 2041 | C13: =E13*'Assumptions & Summary'!$C$23 -> 391431.96 | D13: 0 | E13: =E12*(1+'Assumptions & Summary'!$C$26) -> 9785798.9 | F13: =(('Assumptions & Summary'!$F$16-'Assumptions & Summary'!$F$18-'Assumptions & Summary'!$F$20)*(1+'Assumptions & Summary'!$C$26)^15+'Assumptions & Summary'!$F$18*(1+'Assumptions & Summary'!$C$26)^15+'Assumptions & Summary'!$F$21*(1+'Assumptions & Summary'!$C$26)^15) -> 324057.22 | G13: =(C13*(1-'Assumptions & Summary'!$C$25)+D13*0.85*(1-'Assumptions & Summary'!$C$25))-F13 -> -10911.659 | H13: =E13+I13 -> 16015193 | I13: =I12*(1+'Assumptions & Summary'!$C$24)+J12 -> 6229394.4 | J13: =MAX(0,G13) -> 0 | K13: Mortgage paid off
A14: 67 | B14: 2042 | C14: =E14*'Assumptions & Summary'!$C$23 -> 403174.91 | D14: ='Assumptions & Summary'!$C$12*(1+'Assumptions & Summary'!$C$26)^16 -> 57769.432 | E14: =E13*(1+'Assumptions & Summary'!$C$26) -> 10079373 | F14: =(('Assumptions & Summary'!$F$16-'Assumptions & Summary'!$F$18-'Assumptions & Summary'!$F$20)*(1+'Assumptions & Summary'!$C$26)^16+'Assumptions & Summary'!$F$21*(1+'Assumptions & Summary'!$C$26)^16) -> 285637.75 | G14: =(C14*(1-'Assumptions & Summary'!$C$25)+D14*0.85*(1-'Assumptions & Summary'!$C$25))-F14 -> 76185.399 | H14: =E14+I14 -> 16557943 | I14: =I13*(1+'Assumptions & Summary'!$C$24)+J13 -> 6478570.2 | J14: =MAX(0,G14) -> 76185.399 | K14: SS begins (you only)
A15: 68 | B15: 2043 | C15: =E15*'Assumptions & Summary'!$C$23 -> 415270.16 | D15: ='Assumptions & Summary'!$C$12*(1+'Assumptions & Summary'!$C$26)^17 -> 59502.515 | E15: =E14*(1+'Assumptions & Summary'!$C$26) -> 10381754 | F15: =(('Assumptions & Summary'!$F$16-'Assumptions & Summary'!$F$18-'Assumptions & Summary'!$F$20)*(1+'Assumptions & Summary'!$C$26)^17+'Assumptions & Summary'!$F$21*(1+'Assumptions & Summary'!$C$26)^17) -> 294206.88 | G15: =(C15*(1-'Assumptions & Summary'!$C$25)+D15*0.85*(1-'Assumptions & Summary'!$C$25))-F15 -> 78470.96 | H15: =E15+I15 -> 17195652 | I15: =I14*(1+'Assumptions & Summary'!$C$24)+J14 -> 6813898.4 | J15: =MAX(0,G15) -> 78470.96
A16: 69 | B16: 2044 | C16: =E16*'Assumptions & Summary'!$C$23 -> 427728.27 | D16: ='Assumptions & Summary'!$C$12*(1+'Assumptions & Summary'!$C$26)^18 -> 61287.59 | E16: =E15*(1+'Assumptions & Summary'!$C$26) -> 10693207 | F16: =(('Assumptions & Summary'!$F$16-'Assumptions & Summary'!$F$18-'Assumptions & Summary'!$F$20)*(1+'Assumptions & Summary'!$C$26)^18+'Assumptions & Summary'!$F$21*(1+'Assumptions & Summary'!$C$26)^18) -> 303033.08 | G16: =(C16*(1-'Assumptions & Summary'!$C$25)+D16*0.85*(1-'Assumptions & Summary'!$C$25))-F16 -> 80825.089 | H16: =E16+I16 -> 17858132 | I16: =I15*(1+'Assumptions & Summary'!$C$24)+J15 -> 7164925.3 | J16: =MAX(0,G16) -> 80825.089
A17: 70 | B17: 2045 | C17: =E17*'Assumptions & Summary'!$C$23 -> 440560.11 | D17: ='Assumptions & Summary'!$C$12*(1+'Assumptions & Summary'!$C$26)^19 -> 63126.218 | E17: =E16*(1+'Assumptions & Summary'!$C$26) -> 11014003 | F17: =(('Assumptions & Summary'!$F$16-'Assumptions & Summary'!$F$18-'Assumptions & Summary'!$F$20)*(1+'Assumptions & Summary'!$C$26)^19+'Assumptions & Summary'!$F$21*(1+'Assumptions & Summary'!$C$26)^19) -> 312124.08 | G17: =(C17*(1-'Assumptions & Summary'!$C$25)+D17*0.85*(1-'Assumptions & Summary'!$C$25))-F17 -> 83249.842 | H17: =E17+I17 -> 18546350 | I17: =I16*(1+'Assumptions & Summary'!$C$24)+J16 -> 7532347.4 | J17: =MAX(0,G17) -> 83249.842
A18: 71 | B18: 2046 | C18: =E18*'Assumptions & Summary'!$C$23 -> 453776.92 | D18: ='Assumptions & Summary'!$C$12*(1+'Assumptions & Summary'!$C$26)^20 -> 65020.004 | E18: =E17*(1+'Assumptions & Summary'!$C$26) -> 11344423 | F18: =(('Assumptions & Summary'!$F$16-'Assumptions & Summary'!$F$18-'Assumptions & Summary'!$F$20)*(1+'Assumptions & Summary'!$C$26)^20+'Assumptions & Summary'!$F$21*(1+'Assumptions & Summary'!$C$26)^20) -> 321487.8 | G18: =(C18*(1-'Assumptions & Summary'!$C$25)+D18*0.85*(1-'Assumptions & Summary'!$C$25))-F18 -> 85747.337 | H18: =E18+I18 -> 19261314 | I18: =I17*(1+'Assumptions & Summary'!$C$24)+J17 -> 7916891.1 | J18: =MAX(0,G18) -> 85747.337
A19: 72 | B19: 2047 | C19: =E19*'Assumptions & Summary'!$C$23 -> 467390.22 | D19: ='Assumptions & Summary'!$C$12*(1+'Assumptions & Summary'!$C$26)^21 -> 66970.605 | E19: =E18*(1+'Assumptions & Summary'!$C$26) -> 11684756 | F19: =(('Assumptions & Summary'!$F$16-'Assumptions & Summary'!$F$18-'Assumptions & Summary'!$F$20)*(1+'Assumptions & Summary'!$C$26)^21+'Assumptions & Summary'!$F$21*(1+'Assumptions & Summary'!$C$26)^21) -> 331132.43 | G19: =(C19*(1-'Assumptions & Summary'!$C$25)+D19*0.85*(1-'Assumptions & Summary'!$C$25))-F19 -> 88319.757 | H19: =E19+I19 -> 20004070 | I19: =I18*(1+'Assumptions & Summary'!$C$24)+J18 -> 8319314.1 | J19: =MAX(0,G19) -> 88319.757
A20: 73 | B20: 2048 | C20: =E20*'Assumptions & Summary'!$C$23 -> 481411.93 | D20: ='Assumptions & Summary'!$C$12*(1+'Assumptions & Summary'!$C$26)^22 -> 68979.723 | E20: =E19*(1+'Assumptions & Summary'!$C$26) -> 12035298 | F20: =(('Assumptions & Summary'!$F$16-'Assumptions & Summary'!$F$18-'Assumptions & Summary'!$F$20)*(1+'Assumptions & Summary'!$C$26)^22+'Assumptions & Summary'!$F$21*(1+'Assumptions & Summary'!$C$26)^22) -> 341066.41 | G20: =(C20*(1-'Assumptions & Summary'!$C$25)+D20*0.85*(1-'Assumptions & Summary'!$C$25))-F20 -> 90969.35 | H20: =E20+I20 -> 20775705 | I20: =I19*(1+'Assumptions & Summary'!$C$24)+J19 -> 8740406.4 | J20: =MAX(0,G20) -> 90969.35
A21: 74 | B21: 2049 | C21: =E21*'Assumptions & Summary'!$C$23 -> 495854.29 | D21: ='Assumptions & Summary'!$C$12*(1+'Assumptions & Summary'!$C$26)^23 -> 71049.114 | E21: =E20*(1+'Assumptions & Summary'!$C$26) -> 12396357 | F21: =(('Assumptions & Summary'!$F$16-'Assumptions & Summary'!$F$18-'Assumptions & Summary'!$F$20)*(1+'Assumptions & Summary'!$C$26)^23+'Assumptions & Summary'!$F$21*(1+'Assumptions & Summary'!$C$26)^23) -> 351298.4 | G21: =(C21*(1-'Assumptions & Summary'!$C$25)+D21*0.85*(1-'Assumptions & Summary'!$C$25))-F21 -> 93698.431 | H21: =E21+I21 -> 21577349 | I21: =I20*(1+'Assumptions & Summary'!$C$24)+J20 -> 9180992 | J21: =MAX(0,G21) -> 93698.431
A22: 75 | B22: 2050 | C22: =E22*'Assumptions & Summary'!$C$23 -> 510729.92 | D22: ='Assumptions & Summary'!$C$12*(1+'Assumptions & Summary'!$C$26)^24 -> 73180.588 | E22: =E21*(1+'Assumptions & Summary'!$C$26) -> 12768248 | F22: =(('Assumptions & Summary'!$F$16-'Assumptions & Summary'!$F$18-'Assumptions & Summary'!$F$20)*(1+'Assumptions & Summary'!$C$26)^24+'Assumptions & Summary'!$F$21*(1+'Assumptions & Summary'!$C$26)^24) -> 361837.35 | G22: =(C22*(1-'Assumptions & Summary'!$C$25)+D22*0.85*(1-'Assumptions & Summary'!$C$25))-F22 -> 96509.383 | H22: =E22+I22 -> 22410178 | I22: =I21*(1+'Assumptions & Summary'!$C$24)+J21 -> 9641930.1 | J22: =MAX(0,G22) -> 96509.383
A23: 76 | B23: 2051 | C23: =E23*'Assumptions & Summary'!$C$23 -> 526051.82 | D23: ='Assumptions & Summary'!$C$12*(1+'Assumptions & Summary'!$C$26)^25 -> 75376.005 | E23: =E22*(1+'Assumptions & Summary'!$C$26) -> 13151295 | F23: =(('Assumptions & Summary'!$F$16-'Assumptions & Summary'!$F$18-'Assumptions & Summary'!$F$20)*(1+'Assumptions & Summary'!$C$26)^25+'Assumptions & Summary'!$F$21*(1+'Assumptions & Summary'!$C$26)^25) -> 372692.47 | G23: =(C23*(1-'Assumptions & Summary'!$C$25)+D23*0.85*(1-'Assumptions & Summary'!$C$25))-F23 -> 99404.665 | H23: =E23+I23 -> 23275412 | I23: =I22*(1+'Assumptions & Summary'!$C$24)+J22 -> 10124117 | J23: =MAX(0,G23) -> 99404.665
A24: 77 | B24: 2052 | C24: =E24*'Assumptions & Summary'!$C$23 -> 541833.37 | D24: ='Assumptions & Summary'!$C$12*(1+'Assumptions & Summary'!$C$26)^26 -> 77637.286 | E24: =E23*(1+'Assumptions & Summary'!$C$26) -> 13545834 | F24: =(('Assumptions & Summary'!$F$16-'Assumptions & Summary'!$F$18-'Assumptions & Summary'!$F$20)*(1+'Assumptions & Summary'!$C$26)^26+'Assumptions & Summary'!$F$21*(1+'Assumptions & Summary'!$C$26)^26) -> 383873.25 | G24: =(C24*(1-'Assumptions & Summary'!$C$25)+D24*0.85*(1-'Assumptions & Summary'!$C$25))-F24 -> 102386.8 | H24: =E24+I24 -> 24174320 | I24: =I23*(1+'Assumptions & Summary'!$C$24)+J23 -> 10628486 | J24: =MAX(0,G24) -> 102386.8
A25: 78 | B25: 2053 | C25: =E25*'Assumptions & Summary'!$C$23 -> 558088.37 | D25: ='Assumptions & Summary'!$C$12*(1+'Assumptions & Summary'!$C$26)^27 -> 79966.404 | E25: =E24*(1+'Assumptions & Summary'!$C$26) -> 13952209 | F25: =(('Assumptions & Summary'!$F$16-'Assumptions & Summary'!$F$18-'Assumptions & Summary'!$F$20)*(1+'Assumptions & Summary'!$C$26)^27+'Assumptions & Summary'!$F$21*(1+'Assumptions & Summary'!$C$26)^27) -> 395389.44 | G25: =(C25*(1-'Assumptions & Summary'!$C$25)+D25*0.85*(1-'Assumptions & Summary'!$C$25))-F25 -> 105458.41 | H25: =E25+I25 -> 25108222 | I25: =I24*(1+'Assumptions & Summary'!$C$24)+J24 -> 11156012 | J25: =MAX(0,G25) -> 105458.41
A26: 79 | B26: 2054 | C26: =E26*'Assumptions & Summary'!$C$23 -> 574831.02 | D26: ='Assumptions & Summary'!$C$12*(1+'Assumptions & Summary'!$C$26)^28 -> 82365.396 | E26: =E25*(1+'Assumptions & Summary'!$C$26) -> 14370776 | F26: =(('Assumptions & Summary'!$F$16-'Assumptions & Summary'!$F$18-'Assumptions & Summary'!$F$20)*(1+'Assumptions & Summary'!$C$26)^28+'Assumptions & Summary'!$F$21*(1+'Assumptions & Summary'!$C$26)^28) -> 407251.13 | G26: =(C26*(1-'Assumptions & Summary'!$C$25)+D26*0.85*(1-'Assumptions & Summary'!$C$25))-F26 -> 108622.16 | H26: =E26+I26 -> 26078487 | I26: =I25*(1+'Assumptions & Summary'!$C$24)+J25 -> 11707711 | J26: =MAX(0,G26) -> 108622.16
A27: 80 | B27: 2055 | C27: =E27*'Assumptions & Summary'!$C$23 -> 592075.95 | D27: ='Assumptions & Summary'!$C$12*(1+'Assumptions & Summary'!$C$26)^29 -> 84836.358 | E27: =E26*(1+'Assumptions & Summary'!$C$26) -> 14801899 | F27: =(('Assumptions & Summary'!$F$16-'Assumptions & Summary'!$F$18-'Assumptions & Summary'!$F$20)*(1+'Assumptions & Summary'!$C$26)^29+'Assumptions & Summary'!$F$21*(1+'Assumptions & Summary'!$C$26)^29) -> 419468.66 | G27: =(C27*(1-'Assumptions & Summary'!$C$25)+D27*0.85*(1-'Assumptions & Summary'!$C$25))-F27 -> 111880.83 | H27: =E27+I27 -> 27086541 | I27: =I26*(1+'Assumptions & Summary'!$C$24)+J26 -> 12284642 | J27: =MAX(0,G27) -> 111880.83
A28: 81 | B28: 2056 | C28: =E28*'Assumptions & Summary'!$C$23 -> 609838.23 | D28: ='Assumptions & Summary'!$C$12*(1+'Assumptions & Summary'!$C$26)^30 -> 87381.449 | E28: =E27*(1+'Assumptions & Summary'!$C$26) -> 15245956 | F28: =(('Assumptions & Summary'!$F$16-'Assumptions & Summary'!$F$18-'Assumptions & Summary'!$F$20)*(1+'Assumptions & Summary'!$C$26)^30+'Assumptions & Summary'!$F$21*(1+'Assumptions & Summary'!$C$26)^30) -> 432052.72 | G28: =(C28*(1-'Assumptions & Summary'!$C$25)+D28*0.85*(1-'Assumptions & Summary'!$C$25))-F28 -> 115237.25 | H28: =E28+I28 -> 28133864 | I28: =I27*(1+'Assumptions & Summary'!$C$24)+J27 -> 12887908 | J28: =MAX(0,G28) -> 115237.25
A29: 82 | B29: 2057 | C29: =E29*'Assumptions & Summary'!$C$23 -> 628133.38 | D29: ='Assumptions & Summary'!$C$12*(1+'Assumptions & Summary'!$C$26)^31 -> 90002.892 | E29: =E28*(1+'Assumptions & Summary'!$C$26) -> 15703334 | F29: =(('Assumptions & Summary'!$F$16-'Assumptions & Summary'!$F$18-'Assumptions & Summary'!$F$20)*(1+'Assumptions & Summary'!$C$26)^31+'Assumptions & Summary'!$F$21*(1+'Assumptions & Summary'!$C$26)^31) -> 445014.3 | G29: =(C29*(1-'Assumptions & Summary'!$C$25)+D29*0.85*(1-'Assumptions & Summary'!$C$25))-F29 -> 118694.37 | H29: =E29+I29 -> 29221996 | I29: =I28*(1+'Assumptions & Summary'!$C$24)+J28 -> 13518662 | J29: =MAX(0,G29) -> 118694.37
A30: 83 | B30: 2058 | C30: =E30*'Assumptions & Summary'!$C$23 -> 646977.38 | D30: ='Assumptions & Summary'!$C$12*(1+'Assumptions & Summary'!$C$26)^32 -> 92702.979 | E30: =E29*(1+'Assumptions & Summary'!$C$26) -> 16174435 | F30: =(('Assumptions & Summary'!$F$16-'Assumptions & Summary'!$F$18-'Assumptions & Summary'!$F$20)*(1+'Assumptions & Summary'!$C$26)^32+'Assumptions & Summary'!$F$21*(1+'Assumptions & Summary'!$C$26)^32) -> 458364.73 | G30: =(C30*(1-'Assumptions & Summary'!$C$25)+D30*0.85*(1-'Assumptions & Summary'!$C$25))-F30 -> 122255.2 | H30: =E30+I30 -> 30352537 | I30: =I29*(1+'Assumptions & Summary'!$C$24)+J29 -> 14178103 | J30: =MAX(0,G30) -> 122255.2
A31: 84 | B31: 2059 | C31: =E31*'Assumptions & Summary'!$C$23 -> 666386.7 | D31: ='Assumptions & Summary'!$C$12*(1+'Assumptions & Summary'!$C$26)^33 -> 95484.069 | E31: =E30*(1+'Assumptions & Summary'!$C$26) -> 16659668 | F31: =(('Assumptions & Summary'!$F$16-'Assumptions & Summary'!$F$18-'Assumptions & Summary'!$F$20)*(1+'Assumptions & Summary'!$C$26)^33+'Assumptions & Summary'!$F$21*(1+'Assumptions & Summary'!$C$26)^33) -> 472115.67 | G31: =(C31*(1-'Assumptions & Summary'!$C$25)+D31*0.85*(1-'Assumptions & Summary'!$C$25))-F31 -> 125922.86 | H31: =E31+I31 -> 31527150 | I31: =I30*(1+'Assumptions & Summary'!$C$24)+J30 -> 14867482 | J31: =MAX(0,G31) -> 125922.86
A32: 85 | B32: 2060 | C32: =E32*'Assumptions & Summary'!$C$23 -> 686378.3 | D32: ='Assumptions & Summary'!$C$12*(1+'Assumptions & Summary'!$C$26)^34 -> 98348.591 | E32: =E31*(1+'Assumptions & Summary'!$C$26) -> 17159458 | F32: =(('Assumptions & Summary'!$F$16-'Assumptions & Summary'!$F$18-'Assumptions & Summary'!$F$20)*(1+'Assumptions & Summary'!$C$26)^34+'Assumptions & Summary'!$F$21*(1+'Assumptions & Summary'!$C$26)^34) -> 486279.14 | G32: =(C32*(1-'Assumptions & Summary'!$C$25)+D32*0.85*(1-'Assumptions & Summary'!$C$25))-F32 -> 129700.54 | H32: =E32+I32 -> 32747562 | I32: =I31*(1+'Assumptions & Summary'!$C$24)+J31 -> 15588104 | J32: =MAX(0,G32) -> 129700.54
A33: 86 | B33: 2061 | C33: =E33*'Assumptions & Summary'!$C$23 -> 706969.65 | D33: ='Assumptions & Summary'!$C$12*(1+'Assumptions & Summary'!$C$26)^35 -> 101299.05 | E33: =E32*(1+'Assumptions & Summary'!$C$26) -> 17674241 | F33: =(('Assumptions & Summary'!$F$16-'Assumptions & Summary'!$F$18-'Assumptions & Summary'!$F$20)*(1+'Assumptions & Summary'!$C$26)^35+'Assumptions & Summary'!$F$21*(1+'Assumptions & Summary'!$C$26)^35) -> 500867.52 | G33: =(C33*(1-'Assumptions & Summary'!$C$25)+D33*0.85*(1-'Assumptions & Summary'!$C$25))-F33 -> 133591.56 | H33: =E33+I33 -> 34015570 | I33: =I32*(1+'Assumptions & Summary'!$C$24)+J32 -> 16341329 | J33: =MAX(0,G33) -> 133591.56
A34: 87 | B34: 2062 | C34: =E34*'Assumptions & Summary'!$C$23 -> 728178.74 | D34: ='Assumptions & Summary'!$C$12*(1+'Assumptions & Summary'!$C$26)^36 -> 104338.02 | E34: =E33*(1+'Assumptions & Summary'!$C$26) -> 18204469 | F34: =(('Assumptions & Summary'!$F$16-'Assumptions & Summary'!$F$18-'Assumptions & Summary'!$F$20)*(1+'Assumptions & Summary'!$C$26)^36+'Assumptions & Summary'!$F$21*(1+'Assumptions & Summary'!$C$26)^36) -> 515893.54 | G34: =(C34*(1-'Assumptions & Summary'!$C$25)+D34*0.85*(1-'Assumptions & Summary'!$C$25))-F34 -> 137599.3 | H34: =E34+I34 -> 35333042 | I34: =I33*(1+'Assumptions & Summary'!$C$24)+J33 -> 17128574 | J34: =MAX(0,G34) -> 137599.3
A35: 88 | B35: 2063 | C35: =E35*'Assumptions & Summary'!$C$23 -> 750024.1 | D35: ='Assumptions & Summary'!$C$12*(1+'Assumptions & Summary'!$C$26)^37 -> 107468.16 | E35: =E34*(1+'Assumptions & Summary'!$C$26) -> 18750603 | F35: =(('Assumptions & Summary'!$F$16-'Assumptions & Summary'!$F$18-'Assumptions & Summary'!$F$20)*(1+'Assumptions & Summary'!$C$26)^37+'Assumptions & Summary'!$F$21*(1+'Assumptions & Summary'!$C$26)^37) -> 531370.35 | G35: =(C35*(1-'Assumptions & Summary'!$C$25)+D35*0.85*(1-'Assumptions & Summary'!$C$25))-F35 -> 141727.28 | H35: =E35+I35 -> 36701918 | I35: =I34*(1+'Assumptions & Summary'!$C$24)+J34 -> 17951316 | J35: =MAX(0,G35) -> 141727.28
A36: 89 | B36: 2064 | C36: =E36*'Assumptions & Summary'!$C$23 -> 772524.83 | D36: ='Assumptions & Summary'!$C$12*(1+'Assumptions & Summary'!$C$26)^38 -> 110692.21 | E36: =E35*(1+'Assumptions & Summary'!$C$26) -> 19313121 | F36: =(('Assumptions & Summary'!$F$16-'Assumptions & Summary'!$F$18-'Assumptions & Summary'!$F$20)*(1+'Assumptions & Summary'!$C$26)^38+'Assumptions & Summary'!$F$21*(1+'Assumptions & Summary'!$C$26)^38) -> 547311.46 | G36: =(C36*(1-'Assumptions & Summary'!$C$25)+D36*0.85*(1-'Assumptions & Summary'!$C$25))-F36 -> 145979.1 | H36: =E36+I36 -> 38124216 | I36: =I35*(1+'Assumptions & Summary'!$C$24)+J35 -> 18811096 | J36: =MAX(0,G36) -> 145979.1
A37: 90 | B37: 2065 | C37: =E37*'Assumptions & Summary'!$C$23 -> 795700.57 | D37: ='Assumptions & Summary'!$C$12*(1+'Assumptions & Summary'!$C$26)^39 -> 114012.97 | E37: =E36*(1+'Assumptions & Summary'!$C$26) -> 19892514 | F37: =(('Assumptions & Summary'!$F$16-'Assumptions & Summary'!$F$18-'Assumptions & Summary'!$F$20)*(1+'Assumptions & Summary'!$C$26)^39+'Assumptions & Summary'!$F$21*(1+'Assumptions & Summary'!$C$26)^39) -> 563730.8 | G37: =(C37*(1-'Assumptions & Summary'!$C$25)+D37*0.85*(1-'Assumptions & Summary'!$C$25))-F37 -> 150358.47 | H37: =E37+I37 -> 39602033 | I37: =I36*(1+'Assumptions & Summary'!$C$24)+J36 -> 19709519 | J37: =MAX(0,G37) -> 150358.47 | K37: Plan end

Sheet Accumulation Phase
A1: ACCUMULATION PHASE — AGES 51 TO 57 (WORKING YEARS)
A2: 4% growth portfolio + $150K annual savings
B4: Age | C4: Year | D4: BOY Balance | E4: Savings Added | F4: EOY Balance
B5: 51 | C5: 2026 | D5: 8600000 | E5: 150000 | F5: =(D5+E5)*(1+'Assumptions & Summary'!$C$18) -> 9100000
B6: 52 | C6: 2027 | D6: =F5 -> 9100000 | E6: 150000 | F6: =(D6+E6)*(1+'Assumptions & Summary'!$C$18) -> 9620000
B7: 53 | C7: 2028 | D7: =F6 -> 9620000 | E7: 150000 | F7: =(D7+E7)*(1+'Assumptions & Summary'!$C$18) -> 10160800
B8: 54 | C8: 2029 | D8: =F7 -> 10160800 | E8: 150000 | F8: =(D8+E8)*(1+'Assumptions & Summary'!$C$18) -> 10723232
B9: 55 | C9: 2030 | D9: =F8 -> 10723232 | E9: 150000 | F9: =(D9+E9)*(1+'Assumptions & Summary'!$C$18) -> 11308161
B10: 56 | C10: 2031 | D10: =F9 -> 11308161 | E10: 150000 | F10: =(D10+E10)*(1+'Assumptions & Summary'!$C$18) -> 11916488
B11: Age 57 | D11: =F10 -> 11916488 | E11: Portfolio at retirement
B13: Total Savings Added: | D13: =SUM(E5:E10) -> 900000
B14: Total Investment Growth: | D14: =F10-D5-SUM(E5:E10) -> 2416487.7

Sheet Portfolio Strategy
A1: TWO-SLEEVE PORTFOLIO STRATEGY
A2: Income Sleeve: generates $300K/yr at 4% yield | Growth Sleeve: compounding at 4%
B4: INCOME SLEEVE — $7.5M (51% of portfolio)
B5: Sized at $300K / 4% yield = $7.5M. Generates your living income.
B6: Fund / Ticker | C6: Allocation | D6: Dollar Amt | E6: Notes
B7: VTEB - Vanguard Tax-Exempt Bond | C7: 0.16 | D7: =C7*'Assumptions & Summary'!C19 -> 1900270.4 | E7: Broad national muni; tax-free; 0.03% ER
B8: MUB - iShares National Muni Bond | C8: 0.1 | D8: =C8*'Assumptions & Summary'!C19 -> 1187669 | E8: Investment-grade munis; 6K+ bonds
B9: HYD - VanEck High Yield Muni | C9: 0.08 | D9: =C9*'Assumptions & Summary'!C19 -> 950135.19 | E9: Higher yield munis; ~4.3% yield
B10: VTES - Vanguard Short-Term Tax-Exempt | C10: 0.06 | D10: =C10*'Assumptions & Summary'!C19 -> 712601.39 | E10: Short muni; liquidity buffer
B11: SCHD - Schwab US Dividend Equity | C11: 0.06 | D11: =C11*'Assumptions & Summary'!C19 -> 712601.39 | E11: Quality dividends; ~3.9% yield
B12: JEPI - JPMorgan Equity Premium | C12: 0.05 | D12: =C12*'Assumptions & Summary'!C19 -> 593834.49 | E12: Covered calls; ~7.2% yield; monthly
B13: Income Sleeve Total | C13: =SUM(C7:C12) -> 0.51 | D13: =SUM(D7:D12) -> 6057111.8
B15: GROWTH SLEEVE — $7.25M (49% of portfolio)
B16: Pure growth at 4%. No withdrawals. Surplus reinvested here.
B17: Fund / Ticker | C17: Allocation | D17: Dollar Amt | E17: Notes
B18: VOO - Vanguard S&P 500 | C18: 0.2 | D18: =C18*'Assumptions & Summary'!C19 -> 2375338 | E18: Core US large cap; 0.03% ER
B19: VGT - Vanguard Info Tech | C19: 0.08 | D19: =C19*'Assumptions & Summary'!C19 -> 950135.19 | E19: Tech sector growth; 0.10% ER
B20: VXF - Vanguard Extended Market | C20: 0.06 | D20: =C20*'Assumptions & Summary'!C19 -> 712601.39 | E20: Mid/small cap; 0.06% ER
B21: VXUS - Vanguard Total Intl Stock | C21: 0.08 | D21: =C21*'Assumptions & Summary'!C19 -> 950135.19 | E21: International diversification; 0.07% ER
B22: VIG - Vanguard Dividend Appreciation | C22: 0.07 | D22: =C22*'Assumptions & Summary'!C19 -> 831368.29 | E22: Dividend growers; future income bridge
B23: Growth Sleeve Total | C23: =SUM(C18:C22) -> 0.49 | D23: =SUM(D18:D22) -> 5819578
B25: TOTAL PORTFOLIO | C25: =C13+C23 -> 1 | D25: =D13+D23 -> 11876690
